Workbook

Sheet DASHBOARD
B2: LONGREIN — WEEKLY DASHBOARD
B3: Pirmadienio 8:00 ritualas — užpildyk WEEK_INPUT eilutę, čia pamatysi savaitės status'ą
B5: Dabartinė savaitė #: | C5: 1 | D5: ← keisk šitą skaičių
B7: Mėnuo: | C7: =INDEX(WEEK_INPUT!B:B,$C$5+2) | E7: Savaitės pradžia: | F7: =INDEX(WEEK_INPUT!C:C,$C$5+2) | H7: Master Calendar: | I7: =INDEX(WEEK_INPUT!D:D,$C$5+2)
B9: P0 šią savaitę: | C9: =INDEX(WEEK_INPUT!E:E,$C$5+2)
B11: NORTH STAR — MRR
B12: =INDEX(WEEK_INPUT!Q:Q,$C$5+2)
B14: PIPELINE
B15: FM trial #: | C15: =INDEX(WEEK_INPUT!F:F,$C$5+2) | E15: Demos sched: | F15: =INDEX(WEEK_INPUT!G:G,$C$5+2) | H15: Demos done: | I15: =INDEX(WEEK_INPUT!H:H,$C$5+2)
B16: Paid signups: | C16: =INDEX(WEEK_INPUT!I:I,$C$5+2) | E16: Lost/churn: | F16: =INDEX(WEEK_INPUT!J:J,$C$5+2)
B18: PRODUCT
B19: DAU/WAU %: | C19: =INDEX(WEEK_INPUT!K:K,$C$5+2) | E19: Horses on: | F19: =INDEX(WEEK_INPUT!L:L,$C$5+2) | H19: NPS: | I19: =INDEX(WEEK_INPUT!M:M,$C$5+2)
B20: Open bugs: | C20: =INDEX(WEEK_INPUT!N:N,$C$5+2) | E20: Uptime %: | F20: =INDEX(WEEK_INPUT!O:O,$C$5+2)
B22: FINANSAI
B23: Cash €: | C23: =INDEX(WEEK_INPUT!P:P,$C$5+2) | E23: MRR €: | F23: =INDEX(WEEK_INPUT!Q:Q,$C$5+2) | H23: Burn €: | I23: =INDEX(WEEK_INPUT!R:R,$C$5+2)
B24: Runway (mo): | C24: =INDEX(WEEK_INPUT!S:S,$C$5+2) | E24: AR overdue €: | F24: =INDEX(WEEK_INPUT!T:T,$C$5+2)
B26: MARKETING
B27: IG followers: | C27: =INDEX(WEEK_INPUT!U:U,$C$5+2) | E27: IG reach 7d: | F27: =INDEX(WEEK_INPUT!V:V,$C$5+2) | H27: Landing visits: | I27: =INDEX(WEEK_INPUT!W:W,$C$5+2)
B28: Sign-up rate %: | C28: =INDEX(WEEK_INPUT!X:X,$C$5+2) | E28: Posts shipped: | F28: =INDEX(WEEK_INPUT!Y:Y,$C$5+2) | H28: Email list: | I28: =INDEX(WEEK_INPUT!Z:Z,$C$5+2)
B30: ASMENINĖ DARNA — burnout pulse
B31: Hours Longrein: | C31: =INDEX(WEEK_INPUT!AA:AA,$C$5+2) | E31: Hours TJK: | F31: =INDEX(WEEK_INPUT!AB:AB,$C$5+2) | H31: Sleep h/night: | I31: =INDEX(WEEK_INPUT!AC:AC,$C$5+2)
B32: Riding sessions: | C32: =INDEX(WEEK_INPUT!AD:AD,$C$5+2) | E32: Sunday off? | F32: =INDEX(WEEK_INPUT!AE:AE,$C$5+2)
B33: Energy 1-10: | C33: =INDEX(WEEK_INPUT!AF:AF,$C$5+2) | E33: Cynicism 1-10: | F33: =INDEX(WEEK_INPUT!AG:AG,$C$5+2) | H33: Efficacy 1-10: | I33: =INDEX(WEEK_INPUT!AH:AH,$C$5+2)
B35: STATUS šią savaitę: | C35: =INDEX(WEEK_INPUT!AI:AI,$C$5+2) | E35: Ship done? | F35: =INDEX(WEEK_INPUT!AJ:AJ,$C$5+2) | H35: (R/Y/G arba TAIP/NE rankiniu)
B37: Notes:
B38: =INDEX(WEEK_INPUT!AK:AK,$C$5+2)

Sheet WEEK_INPUT
A1: CONTEXT | F1: PIPELINE | K1: PRODUCT | P1: FINANSAI | U1: MARKETING | AA1: ASMENINĖ | AI1: RETRO
A2: Wk # | B2: Mėnuo | C2: Pradžios data | D2: Master Calendar fazė | E2: P0 šios savaitės | F2: FM trial # | G2: Demos sched | H2: Demos done | I2: Paid signups | J2: Lost/churn | K2: DAU/WAU % | L2: Horses on platform | M2: NPS | N2: Open bugs | O2: Uptime % | P2: Cash € | Q2: MRR € | R2: Burn € | S2: Runway mo | T2: AR overdue € | U2: IG followers | V2: IG reach 7d | W2: Landing visits | X2: Sign-up rate % | Y2: Posts shipped | Z2: Email list | AA2: Hours Longrein | AB2: Hours TJK | AC2: Sleep h/night | AD2: Riding sessions | AE2: Sunday off | AF2: Energy 1-10 | AG2: Cynicism 1-10 | AH2: Efficacy 1-10 | AI2: Status R/Y/G | AJ2: Ship done? | AK2: Notes
A3: 1 | B3: M1 | C3: 46165 | D3: M1 — FM onboarding sprint (week 1)
A4: 2 | B4: M1 | C4: 46172 | D4: M1 — FM onboarding sprint (week 2)
A5: 3 | B5: M1 | C5: 46179 | D5: M1 — FM onboarding sprint (week 3)
A6: 4 | B6: M1 | C6: 46186 | D6: M1 — FM onboarding sprint (week 4)
A7: 5 | B7: M2 | C7: 46193 | D7: M2 — Retention proof
A8: 6 | B8: M2 | C8: 46200
A9: 7 | B9: M2 | C9: 46207
A10: 8 | B10: M2 | C10: 46214
A11: 9 | B11: M3 | C11: 46221 | D11: M3 GATE — Retention gate (8/10 active?)
A12: 10 | B12: M3 | C12: 46228
A13: 11 | B13: M3 | C13: 46235
A14: 12 | B14: M3 | C14: 46242
A15: 13 | B15: M4 | C15: 46249 | D15: M4 — Conversion push begins
A16: 14 | B16: M4 | C16: 46256
A17: 15 | B17: M4 | C17: 46263
A18: 16 | B18: M4 | C18: 46270
A19: 17 | B19: M5 | C19: 46277
A20: 18 | B20: M5 | C20: 46284 | D20: M5 — Conversion + content scale
A21: 19 | B21: M5 | C21: 46291
A22: 20 | B22: M5 | C22: 46298
A23: 21 | B23: M6 | C23: 46305
A24: 22 | B24: M6 | C24: 46312 | D24: M6 GATE — Conversion proof (2+ paid?)
A25: 23 | B25: M6 | C25: 46319
A26: 24 | B26: M6 | C26: 46326
A27: 25 | B27: M7 | C27: 46333
A28: 26 | B28: M7 | C28: 46340
A29: 27 | B29: M7 | C29: 46347 | D29: M7 — Paid customer scale
A30: 28 | B30: M7 | C30: 46354
A31: 29 | B31: M8 | C31: 46361
A32: 30 | B32: M8 | C32: 46368
A33: 31 | B33: M8 | C33: 46375 | D33: M8 — Pre-recalibration analysis
A34: 32 | B34: M8 | C34: 46382
A35: 33 | B35: M9 | C35: 46389
A36: 34 | B36: M9 | C36: 46396
A37: 35 | B37: M9 | C37: 46403 | D37: M9 GATE — Pricing recalibration
A38: 36 | B38: M9 | C38: 46410
A39: 37 | B39: M10 | C39: 46417
A40: 38 | B40: M10 | C40: 46424
...

Sheet TRENDS
A1: TRENDS — auto-generated charts (atsinaujina kai pildai WEEK_INPUT)

Sheet GATES
B2: GATES — kvartaliniai sprendimai
B3: Pildoma 1× per ketvirtį: M3 / M6 / M9 / M12 / M15 / M18. Sprendimas CONTINUE / PIVOT / KILL — be šių sprendimų strategija drift'ina.
B5: M3 GATE — Retention
B6: Date target: | C6: 2026-08-23
B7: KPI: | C7: 8/10 FMs aktyvūs (weekly login)
B8: Actual (fill):
B9: Decision (CONTINUE/PIVOT/KILL):
B10: If FAIL: | C10: ICP recalibration — yra ne tas tipas? funkcijos blogos? onboarding'as silpnas?
B11: Notes / why:
B15: M6 GATE — Conversion
B16: Date target: | C16: 2026-11-23
B17: KPI: | C17: 2+ paid customers, MRR €180+
B18: Actual (fill):
B19: Decision (CONTINUE/PIVOT/KILL):
B20: If FAIL: | C20: Pricing arba messaging klaida — A/B test'uoti pricing page, perskaityti FM exit interviews
B21: Notes / why:
B25: M9 GATE — Pricing
B26: Date target: | C26: 2027-02-23
B27: KPI: | C27: 10 paid customers reached, MRR €900+
B28: Actual (fill):
B29: Decision (CONTINUE/PIVOT/KILL):
B30: If FAIL: | C30: Recalibrate €3/horse — gali tekti pakelti į €3.50 jei retention OK, arba mažinti į €2.50 jei sales blok'inasi
B31: Notes / why:
B35: M12 GATE — Year-1 verdict
B36: Date target: | C36: 2027-05-23
B37: KPI: | C37: 35 paid customers, MRR €3,045, ARR €36,540
B38: Actual (fill):
B39: Decision (CONTINUE/PIVOT/KILL):
B40: If FAIL: | C40: CONTINUE Year 2 (DACH) / PIVOT (B2C? Different vertical?) / KILL (return to TJK only)
B41: Notes / why:
B45: M15 GATE — DACH prep
B46: Date target: | C46: 2027-08-23
B47: KPI: | C47: DE waitlist 200+, EN docs done, DE-native hire pipeline
B48: Actual (fill):
B49: Decision (CONTINUE/PIVOT/KILL):
B50: If FAIL: | C50: Delay DACH 6 mo, focus LT/PL
B51: Notes / why:
B55: M18 GATE — DACH launch
B56: Date target: | C56: 2027-11-23
B57: KPI: | C57: First 3 DE customers, EN/DE landing live
...

Sheet ALERTS_LOG
A1: Data | B1: Wk # | C1: Alert tipas | D1: Metrika | E1: Veiksmas | F1: Rezultatas
A53: Pavyzdžiai 'Alert tipas': BURNOUT / FINANSAI / RETENTION / PIPELINE / PRODUCT

Sheet README
B2: LONGREIN — WEEKLY DASHBOARD YEAR 1
B3: Pildoma kiekvieną pirmadienį 8:00–8:30. Sekmadienio retro 21:50–22:00.
B6: KAIP NAUDOTI
B7: 1) Eik į WEEK_INPUT — pildai 1 eilutę per savaitę, 52 eilutės iš viso.
B8: 2) DASHBOARD sheet automatiškai parodo dabartinę savaitę su alert'ais (žalia/geltona/raudona).
B9: 3) TRENDS sheet — auto-charts (MRR, customers, hours, IG followers).
B10: 4) GATES sheet — pildoma 1× per ketvirtį (M3 / M6 / M9 / M12 — sprendimai CONTINUE / PIVOT / KILL).
B11: 5) ALERTS_LOG — laisva forma rašai kas suveikė tą savaitę ir ką darei.
B13: FAILĄ ATIDARYK PIRMADIENĮ. DURYS UŽDARYTOS. KAVA. 30 MIN. KIEKVIENĄ SAVAITĘ.
B15: DAŽNIAUSIOS KLAIDOS
B16: • Skip'inti pildymą blogą savaitę (ypač tada reikia).
B17: • Pildyti 3 P0 vietoj 1 (1 P0 = vienas. Ne trys.).
... B40: • Longrein-FM-Customer-Success-Playbook-2026-05-02.md (retention metrics)
